<mujoco model="MuJoCo Model">
  <compiler angle="radian"/>

  <worldbody>
    <body name="hinge">
      <body name="stator" pos="-0.05275 0 0">
        <geom name="stator" size="0.05275 0.054 0.052" type="box" mass="0.04158" rgba="0 0.55 0.88 1"/>
      </body>
      <body name="rotor">
        <joint name="servo" pos="0 0 0" axis="0 0 1"/>
        <geom name="rotor" size="0.0447355 0.0519948 0.0519948" pos="0.0447355 0 0" type="box" mass="0.03882" rgba="0 0.25 1 1"/>
        <site name="front" pos="0.0447355 0 0"/>
      </body>
    </body>
  </worldbody>

  <contact>
    <exclude body1="stator" body2="rotor"/>
  </contact>

  <actuator>
    <general name="servo" joint="servo" dynprm="0 0 0 0 0 0 0 0 0 0" biastype="affine" biasprm="0 -1 -1"/>
  </actuator>
</mujoco>
