<mujoco model="MuJoCo Model">
  <compiler angle="radian"/>

  <option integrator="implicitfast"/>

  <visual>
    <global offwidth="1280" offheight="960"/>
  </visual>

  <default>
    <default class="robot-main">
      <default class="robot-0-9-1-main"/>
      <default class="robot-0-29-2-main"/>
      <default class="robot-9-24-0-main"/>
      <default class="robot-29-26-0-main"/>
      <default class="robot-24-10-0-main"/>
      <default class="robot-24-7-3-main"/>
      <default class="robot-7-5-0-main"/>
      <default class="robot-26-20-4-main"/>
      <default class="robot-26-8-0-main"/>
      <default class="robot-20-4-2-main"/>
      <default class="robot-20-19-5-main"/>
      <default class="robot-8-16-5-main"/>
      <default class="robot-8-23-2-main"/>
      <default class="robot-8-1-3-main"/>
      <default class="robot-19-11-0-main"/>
      <default class="robot-11-14-0-main"/>
      <default class="robot-14-17-4-main"/>
      <default class="robot-14-21-3-main"/>
    </default>
  </default>

  <asset>
    <texture type="2d" colorspace="auto" name="grid" builtin="checker" rgb1="0.1 0.2 0.3" rgb2="0.2 0.3 0.4" width="600" height="600"/>
    <material name="grid" texture="grid" texuniform="true" texrepeat="3 3" reflectance="0.2"/>
  </asset>

  <worldbody>
    <geom name="floor" size="1 1 0.1" type="plane" material="grid"/>
    <site pos="0 0 0.208949"/>
    <light name="light" pos="0 0 1" dir="0 0 -1" castshadow="false"/>
    <body name="robot-world" pos="0 0 0.208949">
      <joint type="free"/>
      <body name="robot-core">
        <geom name="robot-core" size="0.1 0.1 0.1" pos="0 0.1 0" type="box" mass="1" rgba="0.992157 0.792157 0.25098 0.5"/>
        <site name="robot-core-front" pos="0 0.2 0"/>
        <site name="robot-core-back" pos="0 0 0" quat="0 0 0 1"/>
        <site name="robot-core-left" pos="-0.1 0.1 0" quat="0.707107 0 0 0.707107"/>
        <site name="robot-core-right" pos="0.1 0.1 0" quat="-0.707107 0 0 0.707107"/>
        <site name="robot-core-top" pos="0 0.1 0.1" quat="0.707107 0.707107 0 0"/>
        <site name="robot-core-bottom" pos="0 0.1 -0.1" quat="0 0 -0.707107 0.707107"/>
        <body name="robot-0-9-1-hinge" quat="0 -0.923785 0 0.382911">
          <body name="robot-0-9-1-stator" pos="0 0.03 0">
            <geom name="robot-0-9-1-stator" size="0.02475 0.0297 0.02475" type="box" mass="0.02" rgba="0.87451 0.160784 0.207843 0.5"/>
          </body>
          <body name="robot-0-9-1-rotor" pos="0 0.08 0">
            <joint name="robot-0-9-1-servo" pos="0 -0.02 0" axis="0 0 1"/>
            <geom name="robot-0-9-1-rotor" size="0.025 0.02 0.025" type="box" mass="0.04" rgba="0.627451 0.0941176 0.129412 0.5"/>
            <site name="robot-0-9-1-hinge-front" pos="0 0.02 0"/>
            <body name="robot-9-24-0-core" pos="0 0.02 0" quat="0.382911 0 0.923785 0">
              <geom name="robot-9-24-0-core" size="0.05 0.05 0.05" pos="0 0.05 0" type="box" mass="0.055" rgba="0.109804 0.466667 0.764706 0.5"/>
              <site name="robot-9-24-0-core-front" pos="0 0.1 0"/>
              <site name="robot-9-24-0-core-left" pos="-0.05 0.05 0" quat="0.707107 0 0 0.707107"/>
              <site name="robot-9-24-0-core-right" pos="0.05 0.05 0" quat="-0.707107 0 0 0.707107"/>
              <site name="robot-9-24-0-core-top" pos="0 0.05 0.05" quat="0.707107 0.707107 0 0"/>
              <site name="robot-9-24-0-core-bottom" pos="0 0.05 -0.05" quat="0 0 -0.707107 0.707107"/>
              <body name="robot-24-10-0-hinge" pos="0 0.1 0" quat="0.707107 0 0.707107 0">
                <body name="robot-24-10-0-stator" pos="0 0.03 0">
                  <geom name="robot-24-10-0-stator" size="0.02475 0.0297 0.02475" type="box" mass="0.02" rgba="0.87451 0.160784 0.207843 0.5"/>
                </body>
                <body name="robot-24-10-0-rotor" pos="0 0.08 0">
                  <joint name="robot-24-10-0-servo" pos="0 -0.02 0" axis="0 0 1"/>
                  <geom name="robot-24-10-0-rotor" size="0.025 0.02 0.025" type="box" mass="0.04" rgba="0.627451 0.0941176 0.129412 0.5"/>
                  <site name="robot-24-10-0-hinge-front" pos="0 0.02 0"/>
                </body>
              </body>
              <body name="robot-24-7-3-hinge" pos="-0.05 0.05 0" quat="0.5 -0.5 0.5 0.5">
                <body name="robot-24-7-3-stator" pos="0 0.03 0">
                  <geom name="robot-24-7-3-stator" size="0.02475 0.0297 0.02475" type="box" mass="0.02" rgba="0.87451 0.160784 0.207843 0.5"/>
                </body>
                <body name="robot-24-7-3-rotor" pos="0 0.08 0">
                  <joint name="robot-24-7-3-servo" pos="0 -0.02 0" axis="0 0 1"/>
                  <geom name="robot-24-7-3-rotor" size="0.025 0.02 0.025" type="box" mass="0.04" rgba="0.627451 0.0941176 0.129412 0.5"/>
                  <site name="robot-24-7-3-hinge-front" pos="0 0.02 0"/>
                  <body name="robot-7-5-0-hinge" pos="0 0.02 0" quat="-0.707107 0 0.707107 0">
                    <body name="robot-7-5-0-stator" pos="0 0.03 0">
                      <geom name="robot-7-5-0-stator" size="0.02475 0.0297 0.02475" type="box" mass="0.02" rgba="0.87451 0.160784 0.207843 0.5"/>
                    </body>
                    <body name="robot-7-5-0-rotor" pos="0 0.08 0">
                      <joint name="robot-7-5-0-servo" pos="0 -0.02 0" axis="0 0 1"/>
                      <geom name="robot-7-5-0-rotor" size="0.025 0.02 0.025" type="box" mass="0.04" rgba="0.627451 0.0941176 0.129412 0.5"/>
                      <site name="robot-7-5-0-hinge-front" pos="0 0.02 0"/>
                    </body>
                  </body>
                </body>
              </body>
            </body>
          </body>
        </body>
        <body name="robot-0-29-2-hinge" pos="0.1 0.1 0" quat="0.5 -0.5 -0.5 -0.5">
          <body name="robot-0-29-2-stator" pos="0 0.03 0">
            <geom name="robot-0-29-2-stator" size="0.02475 0.0297 0.02475" type="box" mass="0.02" rgba="0.87451 0.160784 0.207843 0.5"/>
          </body>
          <body name="robot-0-29-2-rotor" pos="0 0.08 0">
            <joint name="robot-0-29-2-servo" pos="0 -0.02 0" axis="0 0 1"/>
            <geom name="robot-0-29-2-rotor" size="0.025 0.02 0.025" type="box" mass="0.04" rgba="0.627451 0.0941176 0.129412 0.5"/>
            <site name="robot-0-29-2-hinge-front" pos="0 0.02 0"/>
            <body name="robot-29-26-0-core" pos="0 0.02 0" quat="0.707107 0 0.707107 0">
              <geom name="robot-29-26-0-core" size="0.05 0.05 0.05" pos="0 0.05 0" type="box" mass="0.055" rgba="0.109804 0.466667 0.764706 0.5"/>
              <site name="robot-29-26-0-core-front" pos="0 0.1 0"/>
              <site name="robot-29-26-0-core-left" pos="-0.05 0.05 0" quat="0.707107 0 0 0.707107"/>
              <site name="robot-29-26-0-core-right" pos="0.05 0.05 0" quat="-0.707107 0 0 0.707107"/>
              <site name="robot-29-26-0-core-top" pos="0 0.05 0.05" quat="0.707107 0.707107 0 0"/>
              <site name="robot-29-26-0-core-bottom" pos="0 0.05 -0.05" quat="0 0 -0.707107 0.707107"/>
              <body name="robot-26-20-4-core" pos="0 0.05 0.05" quat="0.707107 0.707107 0 0">
                <geom name="robot-26-20-4-core" size="0.05 0.05 0.05" pos="0 0.05 0" type="box" mass="0.055" rgba="0.109804 0.466667 0.764706 0.5"/>
                <site name="robot-26-20-4-core-front" pos="0 0.1 0"/>
                <site name="robot-26-20-4-core-left" pos="-0.05 0.05 0" quat="0.707107 0 0 0.707107"/>
                <site name="robot-26-20-4-core-right" pos="0.05 0.05 0" quat="-0.707107 0 0 0.707107"/>
                <site name="robot-26-20-4-core-top" pos="0 0.05 0.05" quat="0.707107 0.707107 0 0"/>
                <site name="robot-26-20-4-core-bottom" pos="0 0.05 -0.05" quat="0 0 -0.707107 0.707107"/>
                <body name="robot-20-4-2-hinge" pos="0.05 0.05 0" quat="0.5 -0.5 -0.5 -0.5">
                  <body name="robot-20-4-2-stator" pos="0 0.03 0">
                    <geom name="robot-20-4-2-stator" size="0.02475 0.0297 0.02475" type="box" mass="0.02" rgba="0.87451 0.160784 0.207843 0.5"/>
                  </body>
                  <body name="robot-20-4-2-rotor" pos="0 0.08 0">
                    <joint name="robot-20-4-2-servo" pos="0 -0.02 0" axis="0 0 1"/>
                    <geom name="robot-20-4-2-rotor" size="0.025 0.02 0.025" type="box" mass="0.04" rgba="0.627451 0.0941176 0.129412 0.5"/>
                    <site name="robot-20-4-2-hinge-front" pos="0 0.02 0"/>
                  </body>
                </body>
                <body name="robot-20-19-5-hinge" pos="0 0.05 -0.05" quat="0.5 -0.5 -0.5 0.5">
                  <body name="robot-20-19-5-stator" pos="0 0.03 0">
                    <geom name="robot-20-19-5-stator" size="0.02475 0.0297 0.02475" type="box" mass="0.02" rgba="0.87451 0.160784 0.207843 0.5"/>
                  </body>
                  <body name="robot-20-19-5-rotor" pos="0 0.08 0">
                    <joint name="robot-20-19-5-servo" pos="0 -0.02 0" axis="0 0 1"/>
                    <geom name="robot-20-19-5-rotor" size="0.025 0.02 0.025" type="box" mass="0.04" rgba="0.627451 0.0941176 0.129412 0.5"/>
                    <site name="robot-20-19-5-hinge-front" pos="0 0.02 0"/>
                    <body name="robot-19-11-0-hinge" pos="0 0.02 0" quat="-0.707107 0 0.707107 0">
                      <body name="robot-19-11-0-stator" pos="0 0.03 0">
                        <geom name="robot-19-11-0-stator" size="0.02475 0.0297 0.02475" type="box" mass="0.02" rgba="0.87451 0.160784 0.207843 0.5"/>
                      </body>
                      <body name="robot-19-11-0-rotor" pos="0 0.08 0">
                        <joint name="robot-19-11-0-servo" pos="0 -0.02 0" axis="0 0 1"/>
                        <geom name="robot-19-11-0-rotor" size="0.025 0.02 0.025" type="box" mass="0.04" rgba="0.627451 0.0941176 0.129412 0.5"/>
                        <site name="robot-19-11-0-hinge-front" pos="0 0.02 0"/>
                        <body name="robot-11-14-0-core" pos="0 0.02 0" quat="0.707107 0 0.707107 0">
                          <geom name="robot-11-14-0-core" size="0.05 0.05 0.05" pos="0 0.05 0" type="box" mass="0.055" rgba="0.109804 0.466667 0.764706 0.5"/>
                          <site name="robot-11-14-0-core-front" pos="0 0.1 0"/>
                          <site name="robot-11-14-0-core-left" pos="-0.05 0.05 0" quat="0.707107 0 0 0.707107"/>
                          <site name="robot-11-14-0-core-right" pos="0.05 0.05 0" quat="-0.707107 0 0 0.707107"/>
                          <site name="robot-11-14-0-core-top" pos="0 0.05 0.05" quat="0.707107 0.707107 0 0"/>
                          <site name="robot-11-14-0-core-bottom" pos="0 0.05 -0.05" quat="0 0 -0.707107 0.707107"/>
                          <body name="robot-14-17-4-hinge" pos="0 0.05 0.05" quat="0.270759 0.270759 0.653215 0.653215">
                            <body name="robot-14-17-4-stator" pos="0 0.03 0">
                              <geom name="robot-14-17-4-stator" size="0.02475 0.0297 0.02475" type="box" mass="0.02" rgba="0.87451 0.160784 0.207843 0.5"/>
                            </body>
                            <body name="robot-14-17-4-rotor" pos="0 0.08 0">
                              <joint name="robot-14-17-4-servo" pos="0 -0.02 0" axis="0 0 1"/>
                              <geom name="robot-14-17-4-rotor" size="0.025 0.02 0.025" type="box" mass="0.04" rgba="0.627451 0.0941176 0.129412 0.5"/>
                              <site name="robot-14-17-4-hinge-front" pos="0 0.02 0"/>
                            </body>
                          </body>
                          <body name="robot-14-21-3-hinge" pos="-0.05 0.05 0" quat="0.5 -0.5 0.5 0.5">
                            <body name="robot-14-21-3-stator" pos="0 0.03 0">
                              <geom name="robot-14-21-3-stator" size="0.02475 0.0297 0.02475" type="box" mass="0.02" rgba="0.87451 0.160784 0.207843 0.5"/>
                            </body>
                            <body name="robot-14-21-3-rotor" pos="0 0.08 0">
                              <joint name="robot-14-21-3-servo" pos="0 -0.02 0" axis="0 0 1"/>
                              <geom name="robot-14-21-3-rotor" size="0.025 0.02 0.025" type="box" mass="0.04" rgba="0.627451 0.0941176 0.129412 0.5"/>
                              <site name="robot-14-21-3-hinge-front" pos="0 0.02 0"/>
                            </body>
                          </body>
                        </body>
                      </body>
                    </body>
                  </body>
                </body>
              </body>
              <body name="robot-26-8-0-core" pos="0 0.1 0">
                <geom name="robot-26-8-0-core" size="0.05 0.05 0.05" pos="0 0.05 0" type="box" mass="0.055" rgba="0.109804 0.466667 0.764706 0.5"/>
                <site name="robot-26-8-0-core-front" pos="0 0.1 0"/>
                <site name="robot-26-8-0-core-left" pos="-0.05 0.05 0" quat="0.707107 0 0 0.707107"/>
                <site name="robot-26-8-0-core-right" pos="0.05 0.05 0" quat="-0.707107 0 0 0.707107"/>
                <site name="robot-26-8-0-core-top" pos="0 0.05 0.05" quat="0.707107 0.707107 0 0"/>
                <site name="robot-26-8-0-core-bottom" pos="0 0.05 -0.05" quat="0 0 -0.707107 0.707107"/>
                <body name="robot-8-16-5-hinge" pos="0 0.05 -0.05" quat="0.5 -0.5 0.5 -0.5">
                  <body name="robot-8-16-5-stator" pos="0 0.03 0">
                    <geom name="robot-8-16-5-stator" size="0.02475 0.0297 0.02475" type="box" mass="0.02" rgba="0.87451 0.160784 0.207843 0.5"/>
                  </body>
                  <body name="robot-8-16-5-rotor" pos="0 0.08 0">
                    <joint name="robot-8-16-5-servo" pos="0 -0.02 0" axis="0 0 1"/>
                    <geom name="robot-8-16-5-rotor" size="0.025 0.02 0.025" type="box" mass="0.04" rgba="0.627451 0.0941176 0.129412 0.5"/>
                    <site name="robot-8-16-5-hinge-front" pos="0 0.02 0"/>
                  </body>
                </body>
                <body name="robot-8-23-2-hinge" pos="0.05 0.05 0" quat="-0.653215 -0.270759 -0.270759 0.653215">
                  <body name="robot-8-23-2-stator" pos="0 0.03 0">
                    <geom name="robot-8-23-2-stator" size="0.02475 0.0297 0.02475" type="box" mass="0.02" rgba="0.87451 0.160784 0.207843 0.5"/>
                  </body>
                  <body name="robot-8-23-2-rotor" pos="0 0.08 0">
                    <joint name="robot-8-23-2-servo" pos="0 -0.02 0" axis="0 0 1"/>
                    <geom name="robot-8-23-2-rotor" size="0.025 0.02 0.025" type="box" mass="0.04" rgba="0.627451 0.0941176 0.129412 0.5"/>
                    <site name="robot-8-23-2-hinge-front" pos="0 0.02 0"/>
                  </body>
                </body>
                <body name="robot-8-1-3-hinge" pos="-0.05 0.05 0" quat="-0.270759 -0.653215 0.653215 -0.270759">
                  <body name="robot-8-1-3-stator" pos="0 0.03 0">
                    <geom name="robot-8-1-3-stator" size="0.02475 0.0297 0.02475" type="box" mass="0.02" rgba="0.87451 0.160784 0.207843 0.5"/>
                  </body>
                  <body name="robot-8-1-3-rotor" pos="0 0.08 0">
                    <joint name="robot-8-1-3-servo" pos="0 -0.02 0" axis="0 0 1"/>
                    <geom name="robot-8-1-3-rotor" size="0.025 0.02 0.025" type="box" mass="0.04" rgba="0.627451 0.0941176 0.129412 0.5"/>
                    <site name="robot-8-1-3-hinge-front" pos="0 0.02 0"/>
                  </body>
                </body>
              </body>
            </body>
          </body>
        </body>
      </body>
    </body>
  </worldbody>

  <contact>
    <exclude body1="robot-0-9-1-stator" body2="robot-0-9-1-rotor"/>
    <exclude body1="robot-24-10-0-stator" body2="robot-24-10-0-rotor"/>
    <exclude body1="robot-24-7-3-stator" body2="robot-24-7-3-rotor"/>
    <exclude body1="robot-7-5-0-stator" body2="robot-7-5-0-rotor"/>
    <exclude body1="robot-0-29-2-stator" body2="robot-0-29-2-rotor"/>
    <exclude body1="robot-20-4-2-stator" body2="robot-20-4-2-rotor"/>
    <exclude body1="robot-20-19-5-stator" body2="robot-20-19-5-rotor"/>
    <exclude body1="robot-19-11-0-stator" body2="robot-19-11-0-rotor"/>
    <exclude body1="robot-14-17-4-stator" body2="robot-14-17-4-rotor"/>
    <exclude body1="robot-14-21-3-stator" body2="robot-14-21-3-rotor"/>
    <exclude body1="robot-8-16-5-stator" body2="robot-8-16-5-rotor"/>
    <exclude body1="robot-8-23-2-stator" body2="robot-8-23-2-rotor"/>
    <exclude body1="robot-8-1-3-stator" body2="robot-8-1-3-rotor"/>
  </contact>

  <actuator>
    <general name="robot-0-9-1-servo" joint="robot-0-9-1-servo" ctrlrange="-3.14159 -3.14159" dynprm="0 0 0 0 0 0 0 0 0 0" biastype="affine" biasprm="0 -1 -1"/>
    <general name="robot-0-29-2-servo" joint="robot-0-29-2-servo" ctrlrange="-3.14159 -3.14159" dynprm="0 0 0 0 0 0 0 0 0 0" biastype="affine" biasprm="0 -1 -1"/>
    <general name="robot-24-10-0-servo" joint="robot-24-10-0-servo" ctrlrange="-3.14159 -3.14159" dynprm="0 0 0 0 0 0 0 0 0 0" biastype="affine" biasprm="0 -1 -1"/>
    <general name="robot-24-7-3-servo" joint="robot-24-7-3-servo" ctrlrange="-3.14159 -3.14159" dynprm="0 0 0 0 0 0 0 0 0 0" biastype="affine" biasprm="0 -1 -1"/>
    <general name="robot-7-5-0-servo" joint="robot-7-5-0-servo" ctrlrange="-3.14159 -3.14159" dynprm="0 0 0 0 0 0 0 0 0 0" biastype="affine" biasprm="0 -1 -1"/>
    <general name="robot-20-4-2-servo" joint="robot-20-4-2-servo" ctrlrange="-3.14159 -3.14159" dynprm="0 0 0 0 0 0 0 0 0 0" biastype="affine" biasprm="0 -1 -1"/>
    <general name="robot-20-19-5-servo" joint="robot-20-19-5-servo" ctrlrange="-3.14159 -3.14159" dynprm="0 0 0 0 0 0 0 0 0 0" biastype="affine" biasprm="0 -1 -1"/>
    <general name="robot-8-16-5-servo" joint="robot-8-16-5-servo" ctrlrange="-3.14159 -3.14159" dynprm="0 0 0 0 0 0 0 0 0 0" biastype="affine" biasprm="0 -1 -1"/>
    <general name="robot-8-23-2-servo" joint="robot-8-23-2-servo" ctrlrange="-3.14159 -3.14159" dynprm="0 0 0 0 0 0 0 0 0 0" biastype="affine" biasprm="0 -1 -1"/>
    <general name="robot-8-1-3-servo" joint="robot-8-1-3-servo" ctrlrange="-3.14159 -3.14159" dynprm="0 0 0 0 0 0 0 0 0 0" biastype="affine" biasprm="0 -1 -1"/>
    <general name="robot-19-11-0-servo" joint="robot-19-11-0-servo" ctrlrange="-3.14159 -3.14159" dynprm="0 0 0 0 0 0 0 0 0 0" biastype="affine" biasprm="0 -1 -1"/>
    <general name="robot-14-17-4-servo" joint="robot-14-17-4-servo" ctrlrange="-3.14159 -3.14159" dynprm="0 0 0 0 0 0 0 0 0 0" biastype="affine" biasprm="0 -1 -1"/>
    <general name="robot-14-21-3-servo" joint="robot-14-21-3-servo" ctrlrange="-3.14159 -3.14159" dynprm="0 0 0 0 0 0 0 0 0 0" biastype="affine" biasprm="0 -1 -1"/>
  </actuator>
</mujoco>
