<mujoco model="MuJoCo Model">
  <compiler angle="radian"/>

  <option integrator="implicitfast"/>

  <visual>
    <global offwidth="1280" offheight="960"/>
  </visual>

  <default>
    <default class="robot-main">
      <default class="robot-0-20-5-main"/>
      <default class="robot-0-18-0-main"/>
      <default class="robot-18-21-0-main"/>
      <default class="robot-21-3-0-main"/>
      <default class="robot-3-22-0-main"/>
      <default class="robot-22-10-3-main"/>
      <default class="robot-22-11-0-main"/>
      <default class="robot-22-23-2-main"/>
      <default class="robot-10-14-0-main"/>
      <default class="robot-11-12-3-main"/>
      <default class="robot-23-9-3-main"/>
      <default class="robot-23-19-0-main"/>
      <default class="robot-12-24-5-main"/>
      <default class="robot-12-8-2-main"/>
      <default class="robot-19-2-2-main"/>
      <default class="robot-19-15-3-main"/>
      <default class="robot-2-26-0-main"/>
    </default>
  </default>

  <asset>
    <texture type="2d" colorspace="auto" name="grid" builtin="checker" rgb1="0.1 0.2 0.3" rgb2="0.2 0.3 0.4" width="600" height="600"/>
    <material name="grid" texture="grid" texuniform="true" texrepeat="3 3" reflectance="0.2"/>
  </asset>

  <worldbody>
    <geom name="floor" size="1 1 0.1" type="plane" material="grid"/>
    <site pos="0 0 0.395339"/>
    <light name="light" pos="0 0 1" dir="0 0 -1" castshadow="false"/>
    <body name="robot-world" pos="0 0 0.395339">
      <joint type="free"/>
      <body name="robot-core">
        <geom name="robot-core" size="0.1 0.1 0.1" pos="0 0.1 0" type="box" mass="1" rgba="0.992157 0.792157 0.25098 0.5"/>
        <site name="robot-core-front" pos="0 0.2 0"/>
        <site name="robot-core-back" pos="0 0 0" quat="0 0 0 1"/>
        <site name="robot-core-left" pos="-0.1 0.1 0" quat="0.707107 0 0 0.707107"/>
        <site name="robot-core-right" pos="0.1 0.1 0" quat="-0.707107 0 0 0.707107"/>
        <site name="robot-core-top" pos="0 0.1 0.1" quat="0.707107 0.707107 0 0"/>
        <site name="robot-core-bottom" pos="0 0.1 -0.1" quat="0 0 -0.707107 0.707107"/>
        <body name="robot-0-20-5-hinge" pos="0 0.1 -0.1" quat="0.270759 -0.270759 -0.653215 0.653215">
          <body name="robot-0-20-5-stator" pos="0 0.03 0">
            <geom name="robot-0-20-5-stator" size="0.02475 0.0297 0.02475" type="box" mass="0.02" rgba="0.87451 0.160784 0.207843 0.5"/>
          </body>
          <body name="robot-0-20-5-rotor" pos="0 0.08 0">
            <joint name="robot-0-20-5-servo" pos="0 -0.02 0" axis="0 0 1"/>
            <geom name="robot-0-20-5-rotor" size="0.025 0.02 0.025" type="box" mass="0.04" rgba="0.627451 0.0941176 0.129412 0.5"/>
            <site name="robot-0-20-5-hinge-front" pos="0 0.02 0"/>
          </body>
        </body>
        <body name="robot-0-18-0-hinge" pos="0 0.2 0" quat="-0.382911 0 0.923785 0">
          <body name="robot-0-18-0-stator" pos="0 0.03 0">
            <geom name="robot-0-18-0-stator" size="0.02475 0.0297 0.02475" type="box" mass="0.02" rgba="0.87451 0.160784 0.207843 0.5"/>
          </body>
          <body name="robot-0-18-0-rotor" pos="0 0.08 0">
            <joint name="robot-0-18-0-servo" pos="0 -0.02 0" axis="0 0 1"/>
            <geom name="robot-0-18-0-rotor" size="0.025 0.02 0.025" type="box" mass="0.04" rgba="0.627451 0.0941176 0.129412 0.5"/>
            <site name="robot-0-18-0-hinge-front" pos="0 0.02 0"/>
            <body name="robot-18-21-0-hinge" pos="0 0.02 0">
              <body name="robot-18-21-0-stator" pos="0 0.03 0">
                <geom name="robot-18-21-0-stator" size="0.02475 0.0297 0.02475" type="box" mass="0.02" rgba="0.87451 0.160784 0.207843 0.5"/>
              </body>
              <body name="robot-18-21-0-rotor" pos="0 0.08 0">
                <joint name="robot-18-21-0-servo" pos="0 -0.02 0" axis="0 0 1"/>
                <geom name="robot-18-21-0-rotor" size="0.025 0.02 0.025" type="box" mass="0.04" rgba="0.627451 0.0941176 0.129412 0.5"/>
                <site name="robot-18-21-0-hinge-front" pos="0 0.02 0"/>
                <body name="robot-21-3-0-hinge" pos="0 0.02 0" quat="0 0 1 0">
                  <body name="robot-21-3-0-stator" pos="0 0.03 0">
                    <geom name="robot-21-3-0-stator" size="0.02475 0.0297 0.02475" type="box" mass="0.02" rgba="0.87451 0.160784 0.207843 0.5"/>
                  </body>
                  <body name="robot-21-3-0-rotor" pos="0 0.08 0">
                    <joint name="robot-21-3-0-servo" pos="0 -0.02 0" axis="0 0 1"/>
                    <geom name="robot-21-3-0-rotor" size="0.025 0.02 0.025" type="box" mass="0.04" rgba="0.627451 0.0941176 0.129412 0.5"/>
                    <site name="robot-21-3-0-hinge-front" pos="0 0.02 0"/>
                    <body name="robot-3-22-0-core" pos="0 0.02 0" quat="0.707107 0 0.707107 0">
                      <geom name="robot-3-22-0-core" size="0.05 0.05 0.05" pos="0 0.05 0" type="box" mass="0.055" rgba="0.109804 0.466667 0.764706 0.5"/>
                      <site name="robot-3-22-0-core-front" pos="0 0.1 0"/>
                      <site name="robot-3-22-0-core-left" pos="-0.05 0.05 0" quat="0.707107 0 0 0.707107"/>
                      <site name="robot-3-22-0-core-right" pos="0.05 0.05 0" quat="-0.707107 0 0 0.707107"/>
                      <site name="robot-3-22-0-core-top" pos="0 0.05 0.05" quat="0.707107 0.707107 0 0"/>
                      <site name="robot-3-22-0-core-bottom" pos="0 0.05 -0.05" quat="0 0 -0.707107 0.707107"/>
                      <body name="robot-22-10-3-hinge" pos="-0.05 0.05 0" quat="0.270759 -0.653215 0.653215 0.270759">
                        <body name="robot-22-10-3-stator" pos="0 0.03 0">
                          <geom name="robot-22-10-3-stator" size="0.02475 0.0297 0.02475" type="box" mass="0.02" rgba="0.87451 0.160784 0.207843 0.5"/>
                        </body>
                        <body name="robot-22-10-3-rotor" pos="0 0.08 0">
                          <joint name="robot-22-10-3-servo" pos="0 -0.02 0" axis="0 0 1"/>
                          <geom name="robot-22-10-3-rotor" size="0.025 0.02 0.025" type="box" mass="0.04" rgba="0.627451 0.0941176 0.129412 0.5"/>
                          <site name="robot-22-10-3-hinge-front" pos="0 0.02 0"/>
                          <body name="robot-10-14-0-hinge" pos="0 0.02 0" quat="0 0 1 0">
                            <body name="robot-10-14-0-stator" pos="0 0.03 0">
                              <geom name="robot-10-14-0-stator" size="0.02475 0.0297 0.02475" type="box" mass="0.02" rgba="0.87451 0.160784 0.207843 0.5"/>
                            </body>
                            <body name="robot-10-14-0-rotor" pos="0 0.08 0">
                              <joint name="robot-10-14-0-servo" pos="0 -0.02 0" axis="0 0 1"/>
                              <geom name="robot-10-14-0-rotor" size="0.025 0.02 0.025" type="box" mass="0.04" rgba="0.627451 0.0941176 0.129412 0.5"/>
                              <site name="robot-10-14-0-hinge-front" pos="0 0.02 0"/>
                            </body>
                          </body>
                        </body>
                      </body>
                      <body name="robot-22-11-0-core" pos="0 0.1 0" quat="-0.382911 0 0.923785 0">
                        <geom name="robot-22-11-0-core" size="0.05 0.05 0.05" pos="0 0.05 0" type="box" mass="0.055" rgba="0.109804 0.466667 0.764706 0.5"/>
                        <site name="robot-22-11-0-core-front" pos="0 0.1 0"/>
                        <site name="robot-22-11-0-core-left" pos="-0.05 0.05 0" quat="0.707107 0 0 0.707107"/>
                        <site name="robot-22-11-0-core-right" pos="0.05 0.05 0" quat="-0.707107 0 0 0.707107"/>
                        <site name="robot-22-11-0-core-top" pos="0 0.05 0.05" quat="0.707107 0.707107 0 0"/>
                        <site name="robot-22-11-0-core-bottom" pos="0 0.05 -0.05" quat="0 0 -0.707107 0.707107"/>
                        <body name="robot-11-12-3-core" pos="-0.05 0.05 0" quat="-0.270759 -0.653215 0.653215 -0.270759">
                          <geom name="robot-11-12-3-core" size="0.05 0.05 0.05" pos="0 0.05 0" type="box" mass="0.055" rgba="0.109804 0.466667 0.764706 0.5"/>
                          <site name="robot-11-12-3-core-front" pos="0 0.1 0"/>
                          <site name="robot-11-12-3-core-left" pos="-0.05 0.05 0" quat="0.707107 0 0 0.707107"/>
                          <site name="robot-11-12-3-core-right" pos="0.05 0.05 0" quat="-0.707107 0 0 0.707107"/>
                          <site name="robot-11-12-3-core-top" pos="0 0.05 0.05" quat="0.707107 0.707107 0 0"/>
                          <site name="robot-11-12-3-core-bottom" pos="0 0.05 -0.05" quat="0 0 -0.707107 0.707107"/>
                          <body name="robot-12-24-5-core" pos="0 0.05 -0.05" quat="0.5 -0.5 0.5 -0.5">
                            <geom name="robot-12-24-5-core" size="0.05 0.05 0.05" pos="0 0.05 0" type="box" mass="0.055" rgba="0.109804 0.466667 0.764706 0.5"/>
                            <site name="robot-12-24-5-core-front" pos="0 0.1 0"/>
                            <site name="robot-12-24-5-core-left" pos="-0.05 0.05 0" quat="0.707107 0 0 0.707107"/>
                            <site name="robot-12-24-5-core-right" pos="0.05 0.05 0" quat="-0.707107 0 0 0.707107"/>
                            <site name="robot-12-24-5-core-top" pos="0 0.05 0.05" quat="0.707107 0.707107 0 0"/>
                            <site name="robot-12-24-5-core-bottom" pos="0 0.05 -0.05" quat="0 0 -0.707107 0.707107"/>
                          </body>
                          <body name="robot-12-8-2-hinge" pos="0.05 0.05 0" quat="0 -0.707107 -0.707107 0">
                            <body name="robot-12-8-2-stator" pos="0 0.03 0">
                              <geom name="robot-12-8-2-stator" size="0.02475 0.0297 0.02475" type="box" mass="0.02" rgba="0.87451 0.160784 0.207843 0.5"/>
                            </body>
                            <body name="robot-12-8-2-rotor" pos="0 0.08 0">
                              <joint name="robot-12-8-2-servo" pos="0 -0.02 0" axis="0 0 1"/>
                              <geom name="robot-12-8-2-rotor" size="0.025 0.02 0.025" type="box" mass="0.04" rgba="0.627451 0.0941176 0.129412 0.5"/>
                              <site name="robot-12-8-2-hinge-front" pos="0 0.02 0"/>
                            </body>
                          </body>
                        </body>
                      </body>
                      <body name="robot-22-23-2-core" pos="0.05 0.05 0" quat="-0.270759 -0.653215 -0.653215 0.270759">
                        <geom name="robot-22-23-2-core" size="0.05 0.05 0.05" pos="0 0.05 0" type="box" mass="0.055" rgba="0.109804 0.466667 0.764706 0.5"/>
                        <site name="robot-22-23-2-core-front" pos="0 0.1 0"/>
                        <site name="robot-22-23-2-core-left" pos="-0.05 0.05 0" quat="0.707107 0 0 0.707107"/>
                        <site name="robot-22-23-2-core-right" pos="0.05 0.05 0" quat="-0.707107 0 0 0.707107"/>
                        <site name="robot-22-23-2-core-top" pos="0 0.05 0.05" quat="0.707107 0.707107 0 0"/>
                        <site name="robot-22-23-2-core-bottom" pos="0 0.05 -0.05" quat="0 0 -0.707107 0.707107"/>
                        <body name="robot-23-9-3-core" pos="-0.05 0.05 0" quat="0.5 -0.5 0.5 0.5">
                          <geom name="robot-23-9-3-core" size="0.05 0.05 0.05" pos="0 0.05 0" type="box" mass="0.055" rgba="0.109804 0.466667 0.764706 0.5"/>
                          <site name="robot-23-9-3-core-front" pos="0 0.1 0"/>
                          <site name="robot-23-9-3-core-left" pos="-0.05 0.05 0" quat="0.707107 0 0 0.707107"/>
                          <site name="robot-23-9-3-core-right" pos="0.05 0.05 0" quat="-0.707107 0 0 0.707107"/>
                          <site name="robot-23-9-3-core-top" pos="0 0.05 0.05" quat="0.707107 0.707107 0 0"/>
                          <site name="robot-23-9-3-core-bottom" pos="0 0.05 -0.05" quat="0 0 -0.707107 0.707107"/>
                        </body>
                        <body name="robot-23-19-0-core" pos="0 0.1 0">
                          <geom name="robot-23-19-0-core" size="0.05 0.05 0.05" pos="0 0.05 0" type="box" mass="0.055" rgba="0.109804 0.466667 0.764706 0.5"/>
                          <site name="robot-23-19-0-core-front" pos="0 0.1 0"/>
                          <site name="robot-23-19-0-core-left" pos="-0.05 0.05 0" quat="0.707107 0 0 0.707107"/>
                          <site name="robot-23-19-0-core-right" pos="0.05 0.05 0" quat="-0.707107 0 0 0.707107"/>
                          <site name="robot-23-19-0-core-top" pos="0 0.05 0.05" quat="0.707107 0.707107 0 0"/>
                          <site name="robot-23-19-0-core-bottom" pos="0 0.05 -0.05" quat="0 0 -0.707107 0.707107"/>
                          <body name="robot-19-2-2-core" pos="0.05 0.05 0" quat="-0.707107 0 0 0.707107">
                            <geom name="robot-19-2-2-core" size="0.05 0.05 0.05" pos="0 0.05 0" type="box" mass="0.055" rgba="0.109804 0.466667 0.764706 0.5"/>
                            <site name="robot-19-2-2-core-front" pos="0 0.1 0"/>
                            <site name="robot-19-2-2-core-left" pos="-0.05 0.05 0" quat="0.707107 0 0 0.707107"/>
                            <site name="robot-19-2-2-core-right" pos="0.05 0.05 0" quat="-0.707107 0 0 0.707107"/>
                            <site name="robot-19-2-2-core-top" pos="0 0.05 0.05" quat="0.707107 0.707107 0 0"/>
                            <site name="robot-19-2-2-core-bottom" pos="0 0.05 -0.05" quat="0 0 -0.707107 0.707107"/>
                            <body name="robot-2-26-0-hinge" pos="0 0.1 0" quat="-0.382911 0 0.923785 0">
                              <body name="robot-2-26-0-stator" pos="0 0.03 0">
                                <geom name="robot-2-26-0-stator" size="0.02475 0.0297 0.02475" type="box" mass="0.02" rgba="0.87451 0.160784 0.207843 0.5"/>
                              </body>
                              <body name="robot-2-26-0-rotor" pos="0 0.08 0">
                                <joint name="robot-2-26-0-servo" pos="0 -0.02 0" axis="0 0 1"/>
                                <geom name="robot-2-26-0-rotor" size="0.025 0.02 0.025" type="box" mass="0.04" rgba="0.627451 0.0941176 0.129412 0.5"/>
                                <site name="robot-2-26-0-hinge-front" pos="0 0.02 0"/>
                              </body>
                            </body>
                          </body>
                          <body name="robot-19-15-3-core" pos="-0.05 0.05 0" quat="0.653215 -0.270759 0.270759 0.653215">
                            <geom name="robot-19-15-3-core" size="0.05 0.05 0.05" pos="0 0.05 0" type="box" mass="0.055" rgba="0.109804 0.466667 0.764706 0.5"/>
                            <site name="robot-19-15-3-core-front" pos="0 0.1 0"/>
                            <site name="robot-19-15-3-core-left" pos="-0.05 0.05 0" quat="0.707107 0 0 0.707107"/>
                            <site name="robot-19-15-3-core-right" pos="0.05 0.05 0" quat="-0.707107 0 0 0.707107"/>
                            <site name="robot-19-15-3-core-top" pos="0 0.05 0.05" quat="0.707107 0.707107 0 0"/>
                            <site name="robot-19-15-3-core-bottom" pos="0 0.05 -0.05" quat="0 0 -0.707107 0.707107"/>
                          </body>
                        </body>
                      </body>
                    </body>
                  </body>
                </body>
              </body>
            </body>
          </body>
        </body>
      </body>
    </body>
  </worldbody>

  <contact>
    <exclude body1="robot-0-20-5-stator" body2="robot-0-20-5-rotor"/>
    <exclude body1="robot-0-18-0-stator" body2="robot-0-18-0-rotor"/>
    <exclude body1="robot-18-21-0-stator" body2="robot-18-21-0-rotor"/>
    <exclude body1="robot-21-3-0-stator" body2="robot-21-3-0-rotor"/>
    <exclude body1="robot-22-10-3-stator" body2="robot-22-10-3-rotor"/>
    <exclude body1="robot-10-14-0-stator" body2="robot-10-14-0-rotor"/>
    <exclude body1="robot-12-8-2-stator" body2="robot-12-8-2-rotor"/>
    <exclude body1="robot-2-26-0-stator" body2="robot-2-26-0-rotor"/>
  </contact>

  <actuator>
    <general name="robot-0-20-5-servo" joint="robot-0-20-5-servo" ctrlrange="-3.14159 -3.14159" dynprm="0 0 0 0 0 0 0 0 0 0" biastype="affine" biasprm="0 -1 -1"/>
    <general name="robot-0-18-0-servo" joint="robot-0-18-0-servo" ctrlrange="-3.14159 -3.14159" dynprm="0 0 0 0 0 0 0 0 0 0" biastype="affine" biasprm="0 -1 -1"/>
    <general name="robot-18-21-0-servo" joint="robot-18-21-0-servo" ctrlrange="-3.14159 -3.14159" dynprm="0 0 0 0 0 0 0 0 0 0" biastype="affine" biasprm="0 -1 -1"/>
    <general name="robot-21-3-0-servo" joint="robot-21-3-0-servo" ctrlrange="-3.14159 -3.14159" dynprm="0 0 0 0 0 0 0 0 0 0" biastype="affine" biasprm="0 -1 -1"/>
    <general name="robot-22-10-3-servo" joint="robot-22-10-3-servo" ctrlrange="-3.14159 -3.14159" dynprm="0 0 0 0 0 0 0 0 0 0" biastype="affine" biasprm="0 -1 -1"/>
    <general name="robot-10-14-0-servo" joint="robot-10-14-0-servo" ctrlrange="-3.14159 -3.14159" dynprm="0 0 0 0 0 0 0 0 0 0" biastype="affine" biasprm="0 -1 -1"/>
    <general name="robot-12-8-2-servo" joint="robot-12-8-2-servo" ctrlrange="-3.14159 -3.14159" dynprm="0 0 0 0 0 0 0 0 0 0" biastype="affine" biasprm="0 -1 -1"/>
    <general name="robot-2-26-0-servo" joint="robot-2-26-0-servo" ctrlrange="-3.14159 -3.14159" dynprm="0 0 0 0 0 0 0 0 0 0" biastype="affine" biasprm="0 -1 -1"/>
  </actuator>
</mujoco>
